<?xml version="1.0"?>
<robot xmlns:xacro="http://www.ros.org/wiki/xacro" >

    <xacro:include filename="$(find system_description)/urdf/inertia_macros.urdf"/>


    <xacro:property name="base_length" value="0.3"/>
    <xacro:property name="base_width" value="0.3"/>
    <xacro:property name="base_height" value="0.5"/>
    <xacro:property name="base_mass" value="10.0"/>
    <xacro:property name="beam_radius" value="0.05"/>
    <xacro:property name="beam_length" value="1.0"/>
    <xacro:property name="beam_mass" value="1.0"/>

    <material name="white">
        <color rgba="1 1 1 1" />
    </material>

    <material name="orange">
        <color rgba="1 0.3 0.1 1"/>
    </material>

    <material name="blue">
        <color rgba="0.2 0.2 1 1"/>
    </material>

    <material name="black">
        <color rgba="0 0 0 1"/>
    </material>

    <material name="red">
        <color rgba="1 0 0 1"/>
    </material>

    <!-- Used for fixing robot to Gazebo 'base_link' -->
    <link name="world"/>

    <joint name="world_base_joint" type="fixed">
        <parent link="world"/>
        <child link="base_link"/>
    </joint>

    <!-- BASE LINK -->

    <link name="base_link">
        <visual>
            <origin xyz="0 0 ${base_height/2}" rpy="0 0 0"/>
            <geometry>
                <box size="${base_length} ${base_width} ${base_height}"/>
            </geometry>
            <material name="orange"/>
        </visual>
        <collision>
            <origin xyz="0 0 ${base_height/2}"/>
            <geometry>
                <box size="${base_length} ${base_width} ${base_height}"/>
            </geometry>
        </collision>
        <xacro:inertial_box mass="${base_mass}" x="${base_length}" y="${base_width}" z="${base_height}">
            <origin xyz="0 0 ${base_height/2}" rpy="0 0 0"/>
        </xacro:inertial_box>
    </link>

    <gazebo reference="base_link">
        <material>Gazebo/Orange</material>
    </gazebo>

    <!-- BASE TO BEAM JOINT -->

    <joint name="motor_joint" type="revolute">
        <parent link="base_link"/>
        <child link="beam_link"/>
        <origin xyz="${base_width/2} 0 ${base_height/2}" rpy=" ${pi/2} 0 ${pi/2}"/>

        <axis xyz="0 0 1" />
        <limit
            lower="-${pi}"
            upper="${pi}"
            effort="10"
            velocity="3" />
        <dynamics damping="0.1" friction="0.4"/>
    </joint>

    <!-- BEAM LINK -->

    <link name="beam_link">
        <visual>
            <geometry>
                <cylinder radius="${beam_radius}" length="${beam_length}"/>
            </geometry>
            <material name="red"/>
            <origin xyz="0 ${beam_length/2} ${beam_radius}" rpy="0 ${pi/2} ${pi/2}"/>
        </visual>
        <collision>
            <origin xyz="0 ${beam_length/2} ${beam_radius}" rpy="0 ${pi/2} ${pi/2}"/>
            <geometry>
                <cylinder radius="${beam_radius}" length="${beam_length}"/>
            </geometry>
        </collision>
        <xacro:inertial_cylinder mass="${beam_mass}" length="${beam_length}" radius="${beam_radius}">
            <origin xyz="0 ${beam_length/2} ${beam_radius}" rpy="0 ${pi/2} ${pi/2}"/>
        </xacro:inertial_cylinder>
    </link>

    <gazebo reference="beam_link">
        <material>Gazebo/Red</material>
    </gazebo>



</robot>